<robot name="robot_arm">

  <link name="base_link">
    <inertial>
      <origin xyz="0 0 0" rpy="0 0 0"/>
      <mass value="0.0000001"/>
      <inertia ixx="0.0000001" iyy="0.0000001" izz="0.0000001" ixy="0" ixz="0" iyz="0"/>
    </inertial>
    <visual>
      <geometry>
        <box size="0.1 0.1 0.05"/>
      </geometry>
      <origin xyz="0 0 0.025" rpy="0 0 0"/>
    </visual>
  </link>

  <link name="world_link">
    <inertial>
      <origin xyz="0 0 0" rpy="0 0 0"/>
      <mass value="0.0000001"/>
      <inertia ixx="0.0000001" iyy="0.0000001" izz="0.0000001" ixy="0" ixz="0" iyz="0"/>
    </inertial>
  </link>

  <joint name="base_rotation" type="revolute">
    <parent link="world_link"/>
    <child link="base_link"/>
    <origin xyz="0 0 0" rpy="0 0 0"/>
    <axis xyz="0 0 1"/>
    <limit lower="0" upper="6.28" effort="1.0" velocity="1.0"/>
  </joint>

  <link name="link1">
    <inertial>
      <origin xyz="0 0 0" rpy="0 0 0"/>
      <mass value="0.0000001"/>
      <inertia ixx="0.0000001" iyy="0.0000001" izz="0.0000001" ixy="0" ixz="0" iyz="0"/>
    </inertial>
    <visual>
      <geometry>
        <box size="0.21 0.02 0.02"/> </geometry>
      <origin xyz="0.105 0 0" rpy="0 0 0"/> </visual>
  </link>

  <joint name="joint1" type="revolute">
    <parent link="base_link"/>
    <child link="link1"/>
    <origin xyz="0 0 0.05" rpy="0 0 0"/> <axis xyz="0 -1 0"/> <limit lower="0" upper="3.14" effort="1.0" velocity="1.0"/> </joint>

  <link name="link2">
    <inertial>
      <origin xyz="0.21 0 0" rpy="0 0 0"/>
      <mass value="0.0000001"/> <inertia ixx="0.0000001" iyy="0.0000001" izz="0.0000001" ixy="0" ixz="0" iyz="0"/>
    </inertial>
    <visual>
      <geometry>
        <box size="0.21 0.02 0.02"/>
      </geometry>
      <origin xyz="0.105 0 0" rpy="0 0 0"/> </visual>
  </link>

  <joint name="joint2" type="revolute">
    <parent link="link1"/>
    <child link="link2"/>
    <origin xyz="0.21 0 0" rpy="0 0 0"/> <axis xyz="0 -1 0"/> <limit lower="0" upper="2.7" effort="1.0" velocity="1.0"/> </joint>

</robot>